Workbook

Sheet sheet1
A1: ลำดับที่ | B1: รายการของที่คาดว่าจะใช้งาน | C1: รายการ | D1: จำนวน | E1: หน่วย | F1: ราคา/หน่วย | G1: ราคารวม | H1: อ้างอิงราคา
A2: อาคารB ชั้น1
A3: 1 | B3: Reyee Wi-Fi 6 AX1800 RG-RAP62 | C3: Indoor Access Point Wi-Fi 6 AX1800 | D3: 2 | E3: ตัว
A4: 2 | B4: จ้างเหมาติดตั้งสาย LAN พร้อมสาย LAN Outdoor CAT6 พร้อมติดตั้งอุปกรณ์ปลายทาง | C4: จ้างเหมาติดตั้งสาย LAN พร้อมสาย LAN Outdoor CAT6 พร้อมติดตั้งอุปกรณ์ปลายทาง | D4: 2 | E4: จุด
A5: อาคารB ชั้น2
A6: 1 | B6: Mikrotik CCR2004-16G-2S+ | C6: Mikrotik Router | D6: 1 | E6: ตัว
A7: 2 | B7: Wall rack 9U ลึก 50cm. พร้อมพัดลมและถาด | C7: Wall rack 9U พร้อมพัดลมและถาด | D7: 1 | E7: ตู้
A8: 3 | B8: ระบบจัดเก็บ log | C8: ระบบจัดเก็บ log | D8: 1 | E8: ระบบ
A9: 3 | B9: รางไฟชนิด 6 Outlet | C9: รางไฟชนิด 6 Outlet | D9: 1 | E9: ชุด
A10: 4 | B10: Stabilizer ZIRCON 2000VA HD-RL | C10: Stabilizer 1600W | D10: 1 | E10: ตัว
A11: 5 | B11: Reyee RG-NBS3100-24GT4SFP-P | C11: Managed Switch 24 port PoE | D11: 1 | E11: ตัว
A12: 6 | B12: Reyee Wi-Fi 6 AX1800 RG-RAP62 | C12: Indoor Access Point Wi-Fi 6 AX1800 | D12: 3 | E12: ตัว
A13: 7 | B13: จ้างเหมาติดตั้งสาย LAN พร้อมสาย LAN Indoor CAT6 พร้อมติดตั้งอุปกรณ์ปลายทาง(ร้อยสายในท่อ pvc) | C13: จ้างเหมาติดตั้งสาย LAN พร้อมสาย LAN Indoor CAT6 พร้อมติดตั้งอุปกรณ์ปลายทาง(ร้อยสายในท่อ pvc) | D13: 3 | E13: จุด
A14: 8 | B14: จ้างเหมาติดตั้งตู้ rack พร้อมเชื่อมต่อไฟฟ้าเข้าตู้ rack | C14: จ้างเหมาติดตั้งตู้ rack พร้อมเชื่อมต่อไฟฟ้าเข้าตู้ rack | D14: 1 | E14: งาน
A15: 9 | B15: จ้างเหมาติดตั้งระบบ Ground ของตู้ Rack พร้อม Ground rod และ Bus bas | C15: จ้างเหมาติดตั้งระบบ Ground ของตู้ Rack พร้อม Ground rod และ Bus bas | D15: 1 | E15: งาน
A16: อาคารA ชั้น1
A17: 1 | B17: Wall Rack 6U (50 cm.) GERMANY พร้อมพัดลมเดี่ยว 4 นิ้ว | C17: Wall Rack 6U (50 cm.) GERMANY พร้อมพัดลมเดี่ยว 4 นิ้ว | D17: 1 | E17: ตู้
A18: 2 | B18: Reyee RG-NBS3100-24GT4SFP-P | C18: Managed Switch 24 port PoE | D18: 1 | E18: ตัว
A19: 3 | B19: Stabilizer ZIRCON 2000VA HD-RL | C19: Stabilizer 1600W | D19: 1 | E19: ตัว
A20: 4 | B20: Reyee Wi-Fi 6 AX1800 RG-RAP62 | C20: Indoor Access Point Wi-Fi 6 AX1800 | D20: 2 | E20: ตัว
A21: 5 | B21: CAT6 LAN Patch cord 1 เมตร | C21: CAT6 LAN Patch cord 1 เมตร | D21: 3 | E21: เส้น
A22: 7 | B22: จ้างเหมาติดตั้งสาย LAN พร้อมสาย LAN Indoor CAT6 พร้อมติดตั้ง Lan Outlet | C22: จ้างเหมาติดตั้งสาย LAN พร้อมสาย LAN Indoor CAT6 พร้อมติดตั้ง Lan Outlet | D22: 12 | E22: จุด
A23: 8 | B23: จ้างเหมาติดตั้งสาย LAN พร้อมสาย LAN Outdoor CAT6 พร้อมติดตั้งอุปกรณ์ปลายทาง | C23: จ้างเหมาติดตั้งสาย LAN พร้อมสาย LAN Outdoor CAT6 พร้อมติดตั้งอุปกรณ์ปลายทาง | D23: 3 | E23: จุด
A24: 9 | B24: จ้างเหมาติดตั้งตู้ rack พร้อมเชื่อมต่อไฟฟ้าเข้าตู้ rack | C24: จ้างเหมาติดตั้งตู้ rack พร้อมเชื่อมต่อไฟฟ้าเข้าตู้ rack | D24: 1 | E24: งาน
A25: 10 | B25: จ้างเหมาติดตั้งระบบ Ground ของตู้ Rack พร้อม Ground rod และ Bus bas | C25: จ้างเหมาติดตั้งระบบ Ground ของตู้ Rack พร้อม Ground rod และ Bus bas | D25: 1 | E25: งาน
A26: อาคารA ชั้น2
A27: 1 | B27: Reyee Wi-Fi 6 AX1800 RG-RAP62 | C27: Indoor Access Point Wi-Fi 6 AX1800 | D27: 2 | E27: ตัว
A28: 2 | B28: Switch Reyee RG-ES224GC-V2 | C28: Switch managed 24 port | D28: 1 | E28: ตัว
A29: 3 | B29: จ้างเหมาติดตั้งสาย LAN พร้อมสาย LAN Indoor CAT6 พร้อมติดตั้ง Lan Outlet | C29: จ้างเหมาติดตั้งสาย LAN พร้อมสาย LAN Indoor CAT6 พร้อมติดตั้ง Lan Outlet | D29: 2 | E29: จุด
A30: 4 | B30: จ้างเหมาติดตั้งสาย LAN พร้อมสาย LAN Outdoor CAT6 พร้อมติดตั้งอุปกรณ์ปลายทาง | C30: จ้างเหมาติดตั้งสาย LAN พร้อมสาย LAN Outdoor CAT6 พร้อมติดตั้งอุปกรณ์ปลายทาง | D30: 2 | E30: จุด
A31: อาคารC
A32: 1 | B32: Reyee Wi-Fi 6 AX1800 RG-RAP62 | C32: Indoor Access Point Wi-Fi 6 AX1800 | D32: 1 | E32: ตัว
A33: 2 | B33: RG-ES210GS-P | C33: Managed Switch 8 port PoE | D33: 1 | E33: ตัว
A34: 3 | B34: จ้างเหมาติดตั้งสาย LAN พร้อมสาย LAN Outdoor CAT6 พร้อมติดตั้งอุปกรณ์ปลายทาง | C34: จ้างเหมาติดตั้งสาย LAN พร้อมสาย LAN Outdoor CAT6 พร้อมติดตั้งอุปกรณ์ปลายทาง | D34: 2 | E34: จุด
A35: อาคาร D และหอประชุม
A36: 1 | B36: Reyee Wi-Fi 6 AX1800 RG-RAP62 | C36: Indoor Access Point Wi-Fi 6 AX1800 | D36: 2 | E36: ตัว
A37: 2 | B37: RG-RAP2260(E) Reyee Wi-Fi 6 AX3200 | C37: Indoor Access Point Wi-Fi 6 AX3200 | D37: 1 | E37: ตัว
A38: 3 | B38: RG-ES210GS-P | C38: Managed Switch 8 port PoE | D38: 1 | E38: ตัว
A39: 4 | B39: 1.25Gpbs Bidi SFP Module | C39: 1.25Gpbs Bidi SFP Module | D39: 1 | E39: ตัว
A40: 5 | B40: Stabilizer ZIRCON 2000VA HD-RL | C40: Stabilizer 1600W | D40: 1 | E40: ตัว
...

Sheet TOR_list
A1: ลำดับที่ | B1: รายการ | C1: จำนวน
A2: =IF(B2="","",COUNTIF($B$3:B3,"<>")) -> 1 | B2: {=_xlfn.UNIQUE(_xlfn._xlws.FILTER(sheet1!B3:B100,sheet1!B3:B100<>""))} -> Reyee Wi-Fi 6 AX1800 RG-RAP62 | C2: =SUMIF(sheet1!$B$3:$B$100,B2,sheet1!$D$3:$D$100) -> 12
A3: =IF(B3="","",COUNTIF($B$3:B4,"<>")) -> 2 | B3: จ้างเหมาติดตั้งสาย LAN พร้อมสาย LAN Outdoor CAT6 พร้อมติดตั้งอุปกรณ์ปลายทาง | C3: =SUMIF(sheet1!$B$3:$B$100,B3,sheet1!$D$3:$D$100) -> 10
A4: =IF(B4="","",COUNTIF($B$3:B5,"<>")) -> 3 | B4: Mikrotik CCR2004-16G-2S+ | C4: =SUMIF(sheet1!$B$3:$B$100,B4,sheet1!$D$3:$D$100) -> 1
A5: =IF(B5="","",COUNTIF($B$3:B6,"<>")) -> 4 | B5: Wall rack 9U ลึก 50cm. พร้อมพัดลมและถาด | C5: =SUMIF(sheet1!$B$3:$B$100,B5,sheet1!$D$3:$D$100) -> 2
A6: =IF(B6="","",COUNTIF($B$3:B7,"<>")) -> 5 | B6: ระบบจัดเก็บ log | C6: =SUMIF(sheet1!$B$3:$B$100,B6,sheet1!$D$3:$D$100) -> 1
A7: =IF(B7="","",COUNTIF($B$3:B8,"<>")) -> 6 | B7: รางไฟชนิด 6 Outlet | C7: =SUMIF(sheet1!$B$3:$B$100,B7,sheet1!$D$3:$D$100) -> 1
A8: =IF(B8="","",COUNTIF($B$3:B9,"<>")) -> 7 | B8: Stabilizer ZIRCON 2000VA HD-RL | C8: =SUMIF(sheet1!$B$3:$B$100,B8,sheet1!$D$3:$D$100) -> 3
A9: =IF(B9="","",COUNTIF($B$3:B10,"<>")) -> 8 | B9: Reyee RG-NBS3100-24GT4SFP-P | C9: =SUMIF(sheet1!$B$3:$B$100,B9,sheet1!$D$3:$D$100) -> 2
A10: =IF(B10="","",COUNTIF($B$3:B11,"<>")) -> 9 | B10: จ้างเหมาติดตั้งสาย LAN พร้อมสาย LAN Indoor CAT6 พร้อมติดตั้งอุปกรณ์ปลายทาง(ร้อยสายในท่อ pvc) | C10: =SUMIF(sheet1!$B$3:$B$100,B10,sheet1!$D$3:$D$100) -> 6
A11: =IF(B11="","",COUNTIF($B$3:B12,"<>")) -> 10 | B11: จ้างเหมาติดตั้งตู้ rack พร้อมเชื่อมต่อไฟฟ้าเข้าตู้ rack | C11: =SUMIF(sheet1!$B$3:$B$100,B11,sheet1!$D$3:$D$100) -> 3
A12: =IF(B12="","",COUNTIF($B$3:B13,"<>")) -> 11 | B12: จ้างเหมาติดตั้งระบบ Ground ของตู้ Rack พร้อม Ground rod และ Bus bas | C12: =SUMIF(sheet1!$B$3:$B$100,B12,sheet1!$D$3:$D$100) -> 3
A13: =IF(B13="","",COUNTIF($B$3:B14,"<>")) -> 12 | B13: Wall Rack 6U (50 cm.) GERMANY พร้อมพัดลมเดี่ยว 4 นิ้ว | C13: =SUMIF(sheet1!$B$3:$B$100,B13,sheet1!$D$3:$D$100) -> 1
A14: =IF(B14="","",COUNTIF($B$3:B15,"<>")) -> 13 | B14: CAT6 LAN Patch cord 1 เมตร | C14: =SUMIF(sheet1!$B$3:$B$100,B14,sheet1!$D$3:$D$100) -> 3
... A20: =IF(B20="","",COUNTIF($B$3:B21,"<>")) -> 18 | B20: จ้างเหมาเดินสาย OFC 2C ระยะไม่เกิน 200 เมตร พร้อมสายและ Fusion Splice | C20: =SUMIF(sheet1!$B$3:$B$100,B20,sheet1!$D$3:$D$100) -> 1
